Workbook
Name cop: #REF!
Name Slicer_City: #N/A
Name Slicer_Product_ID: #N/A

Sheet Sheet1
A1: Delivery_Charge | B1: (Multiple Items)
A3: Row Labels | B3: Distinct Count of Customer_ID | C3: Sum of Order Amount2 | D3: Average of Age | E3: Count of Order_ID | F3: Distinct Count of Product_ID | G3: Sum of Order Amount
A4: Jodi Whitney | B4: 1 | C4: 14040.5 | D4: 33 | E4: 11 | F4: 8 | G4: 14040.5
A5: Lauren Crane | B5: 1 | C5: 8918.13 | D5: 62 | E5: 10 | F5: 10 | G5: 8918.13
A6: Mark Summers | B6: 1 | C6: 8409.26 | D6: 55 | E6: 11 | F6: 10 | G6: 8409.26
A7: Mary Knight | B7: 1 | C7: 7661.22 | D7: 28 | E7: 10 | F7: 9 | G7: 7661.22
A8: Lauren Long | B8: 1 | C8: 7387.72 | D8: 44 | E8: 8 | F8: 8 | G8: 7387.72
A9: Brendan Kelly | B9: 1 | C9: 7072.31 | D9: 50 | E9: 10 | F9: 7 | G9: 7072.31
A10: Jessica Ruiz | B10: 1 | C10: 7057.88 | D10: 19 | E10: 6 | F10: 5 | G10: 7057.88
A11: Katherine Weber | B11: 1 | C11: 6823.27 | D11: 42 | E11: 6 | F11: 5 | G11: 6823.27
A12: John Herrera | B12: 1 | C12: 6811.95 | D12: 64 | E12: 7 | F12: 6 | G12: 6811.95
A13: Angela Evans | B13: 1 | C13: 6799.51 | D13: 52 | E13: 10 | F13: 9 | G13: 6799.51
A14: Alexandra Smith | B14: 1 | C14: 6318.69 | D14: 70 | E14: 6 | F14: 6 | G14: 6318.69
A15: Erin Miller | B15: 1 | C15: 6283.51 | D15: 46 | E15: 7 | F15: 6 | G15: 6283.51
... A104: Grand Total | B104: 100 | C104: 364289.49 | D104: 42.124 | E104: 500 | F104: 50 | G104: 364289.49

Sheet Final Data  
A1: Customer_ID | B1: First_Name | C1: Last_Name | D1: Age | E1: Gender | F1: City | G1: Email | H1: Address | I1: Order_ID | J1: Order_Date | K1: Order_Time | L1: Product_ID | M1: Price | N1: Quantity | O1: Coupon_Code | P1: Estimated_Days_to_Deliver | Q1: Delivery_Charge | R1: Delivery_Date | S1: Delivery_Time | T1: Full name | U1: Order Amount | V1: Days it took for delivery | W1: Discount_Percent | X1: Adjusted sales | Y1: Discounted Amount | Z1: Amount After Discount | AA1: Amount_with_delivery_charge | AB1: Delivery_Status | AC1: Order_Month
A2: CID186 | B2: Anne | C2: Oconnell | D2: 37 | E2: Male | F2: Phoenix | G2: anne.oconnell@outlook.com | H2: 2850 Matthew Ford, North Yolandachester, FL 67488 | I2: OID2497 | J2: 45358 | K2: 18:16:33 | L2: PID022 | M2: 308.88 | N2: 5 | O2: FLAT8 | P2: 4 | Q2: 60 | R2: 45361 | S2: 08:51:31 | T2: =_xlfn.CONCAT(B2," ",C2) -> Anne Oconnell | U2: =M2*N2 -> 1544.4 | V2: =R2-J2 -> 3 | W2: =IF(O2="FLAT8",8%,IF(O2="FLAT10",10%,IF(O2="FLAT15",15%,IF(O2="FLAT20",20%,0)))) -> 0.08 | X2: =U2-(U2*W2)+IF(O2="DEL0",0,Q2) -> 1480.848 | Y2: =U2*W2 -> 123.552 | Z2: =U2-Y2 -> 1420.848 | AA2: =Z2+IF(O2="DEL0",0,Q2) -> 1480.848 | AB2: =IF(V2>5,"Late",IF(V2=5,"Intime","BeforeTime")) -> BeforeTime | AC2: =TEXT(J2,"mmmm") -> March
A3: CID150 | B3: Anthony | C3: Thomas | D3: 53 | E3: Female | F3: Houston | G3: anthony.thomas@rediffmail.com | H3: 931 Christopher Ways Suite 833, North Michelle, IN 53484 | I3: OID7056 | J3: 45378 | K3: 01:46:33 | L3: PID015 | M3: 166.28 | N3: 4 | O3: FLAT8 | P3: 7 | Q3: 66 | R3: 45381 | S3: 18:46:26 | T3: =_xlfn.CONCAT(B3," ",C3) -> Anthony Thomas | U3: =M3*N3 -> 665.12 | V3: =R3-J3 -> 3 | W3: =IF(O3="FLAT8",8%,IF(O3="FLAT10",10%,IF(O3="FLAT15",15%,IF(O3="FLAT20",20%,0)))) -> 0.08 | X3: =U3-(U3*W3)+IF(O3="DEL0",0,Q3) -> 677.9104 | Y3: =U3*W3 -> 53.2096 | Z3: =U3-Y3 -> 611.9104 | AA3: =Z3+IF(O3="DEL0",0,Q3) -> 677.9104 | AB3: =IF(V3>5,"Late",IF(V3=5,"Intime","BeforeTime")) -> BeforeTime | AC3: =TEXT(J3,"mmmm") -> March
A4: CID115 | B4: Karl | C4: Gallagher | D4: 60 | E4: Other | F4: Phoenix | G4: karl.gallagher@rediffmail.com | H4: 5016 Snow Mountains Apt. 063, New Seanport, WY 41492 | I4: OID7502 | J4: 45342 | K4: 07:31:36 | L4: PID023 | M4: 202.54 | N4: 1 | O4: FLAT15 | P4: 3 | Q4: 47 | R4: 45344 | S4: 14:29:50 | T4: =_xlfn.CONCAT(B4," ",C4) -> Karl Gallagher | U4: =M4*N4 -> 202.54 | V4: =R4-J4 -> 2 | W4: =IF(O4="FLAT8",8%,IF(O4="FLAT10",10%,IF(O4="FLAT15",15%,IF(O4="FLAT20",20%,0)))) -> 0.15 | X4: =U4-(U4*W4)+IF(O4="DEL0",0,Q4) -> 219.159 | Y4: =U4*W4 -> 30.381 | Z4: =U4-Y4 -> 172.159 | AA4: =Z4+IF(O4="DEL0",0,Q4) -> 219.159 | AB4: =IF(V4>5,"Late",IF(V4=5,"Intime","BeforeTime")) -> BeforeTime | AC4: =TEXT(J4,"mmmm") -> February
A5: CID115 | B5: Karl | C5: Gallagher | D5: 60 | E5: Other | F5: Phoenix | G5: karl.gallagher@rediffmail.com | H5: 5016 Snow Mountains Apt. 063, New Seanport, WY 41492 | I5: OID7077 | J5: 45426 | K5: 18:29:21 | L5: PID031 | M5: 405 | N5: 5 | O5: DEL0 | P5: 6 | Q5: 47 | R5: 45430 | S5: 07:00:32 | T5: =_xlfn.CONCAT(B5," ",C5) -> Karl Gallagher | U5: =M5*N5 -> 2025 | V5: =R5-J5 -> 4 | W5: =IF(O5="FLAT8",8%,IF(O5="FLAT10",10%,IF(O5="FLAT15",15%,IF(O5="FLAT20",20%,0)))) -> 0 | X5: =U5-(U5*W5)+IF(O5="DEL0",0,Q5) -> 2025 | Y5: =U5*W5 -> 0 | Z5: =U5-Y5 -> 2025 | AA5: =Z5+IF(O5="DEL0",0,Q5) -> 2025 | AB5: =IF(V5>5,"Late",IF(V5=5,"Intime","BeforeTime")) -> BeforeTime | AC5: =TEXT(J5,"mmmm") -> May
A6: CID149 | B6: Angela | C6: Horne | D6: 49 | E6: Other | F6: Phoenix | G6: angela.horne@outlook.com | H6: USNV Mueller, FPO AP 54648 | I6: OID2793 | J6: 45391 | K6: 03:23:21 | L6: PID015 | M6: 166.28 | N6: 1 | O6: FLAT8 | P6: 2 | Q6: 54 | R6: 45395 | S6: 22:10:58 | T6: =_xlfn.CONCAT(B6," ",C6) -> Angela Horne | U6: =M6*N6 -> 166.28 | V6: =R6-J6 -> 4 | W6: =IF(O6="FLAT8",8%,IF(O6="FLAT10",10%,IF(O6="FLAT15",15%,IF(O6="FLAT20",20%,0)))) -> 0.08 | X6: =U6-(U6*W6)+IF(O6="DEL0",0,Q6) -> 206.9776 | Y6: =U6*W6 -> 13.3024 | Z6: =U6-Y6 -> 152.9776 | AA6: =Z6+IF(O6="DEL0",0,Q6) -> 206.9776 | AB6: =IF(V6>5,"Late",IF(V6=5,"Intime","BeforeTime")) -> BeforeTime | AC6: =TEXT(J6,"mmmm") -> April
A7: CID159 | B7: Christine | C7: West | D7: 53 | E7: Other | F7: New York | G7: christine.west@gmail.com | H7: Unit 1433 Box 0246, DPO AP 94952 | I7: OID1483 | J7: 45543 | K7: 16:55:06 | L7: PID043 | M7: 330.11 | N7: 4 | O7: FLAT15 | P7: 6 | Q7: 39 | R7: 45547 | S7: 11:25:50 | T7: =_xlfn.CONCAT(B7," ",C7) -> Christine West | U7: =M7*N7 -> 1320.44 | V7: =R7-J7 -> 4 | W7: =IF(O7="FLAT8",8%,IF(O7="FLAT10",10%,IF(O7="FLAT15",15%,IF(O7="FLAT20",20%,0)))) -> 0.15 | X7: =U7-(U7*W7)+IF(O7="DEL0",0,Q7) -> 1161.374 | Y7: =U7*W7 -> 198.066 | Z7: =U7-Y7 -> 1122.374 | AA7: =Z7+IF(O7="DEL0",0,Q7) -> 1161.374 | AB7: =IF(V7>5,"Late",IF(V7=5,"Intime","BeforeTime")) -> BeforeTime | AC7: =TEXT(J7,"mmmm") -> September
A8: CID115 | B8: Karl | C8: Gallagher | D8: 60 | E8: Other | F8: Phoenix | G8: karl.gallagher@rediffmail.com | H8: 5016 Snow Mountains Apt. 063, New Seanport, WY 41492 | I8: OID4105 | J8: 45662 | K8: 09:47:21 | L8: PID022 | M8: 308.88 | N8: 5 | O8: FLAT20 | P8: 5 | Q8: 47 | R8: 45665 | S8: 20:10:50 | T8: =_xlfn.CONCAT(B8," ",C8) -> Karl Gallagher | U8: =M8*N8 -> 1544.4 | V8: =R8-J8 -> 3 | W8: =IF(O8="FLAT8",8%,IF(O8="FLAT10",10%,IF(O8="FLAT15",15%,IF(O8="FLAT20",20%,0)))) -> 0.2 | X8: =U8-(U8*W8)+IF(O8="DEL0",0,Q8) -> 1282.52 | Y8: =U8*W8 -> 308.88 | Z8: =U8-Y8 -> 1235.52 | AA8: =Z8+IF(O8="DEL0",0,Q8) -> 1282.52 | AB8: =IF(V8>5,"Late",IF(V8=5,"Intime","BeforeTime")) -> BeforeTime | AC8: =TEXT(J8,"mmmm") -> January
A9: CID198 | B9: David | C9: Delacruz | D9: 26 | E9: Female | F9: Los Angeles | G9: david.delacruz@rediffmail.com | H9: USNS Ray, FPO AE 20238 | I9: OID4372 | J9: 45459 | K9: 19:27:45 | L9: PID046 | M9: 363.64 | N9: 3 | O9: FLAT10 | P9: 2 | Q9: 70 | R9: 45464 | S9: 12:36:32 | T9: =_xlfn.CONCAT(B9," ",C9) -> David Delacruz | U9: =M9*N9 -> 1090.92 | V9: =R9-J9 -> 5 | W9: =IF(O9="FLAT8",8%,IF(O9="FLAT10",10%,IF(O9="FLAT15",15%,IF(O9="FLAT20",20%,0)))) -> 0.1 | X9: =U9-(U9*W9)+IF(O9="DEL0",0,Q9) -> 1051.828 | Y9: =U9*W9 -> 109.092 | Z9: =U9-Y9 -> 981.828 | AA9: =Z9+IF(O9="DEL0",0,Q9) -> 1051.828 | AB9: =IF(V9>5,"Late",IF(V9=5,"Intime","BeforeTime")) -> Intime | AC9: =TEXT(J9,"mmmm") -> June
A10: CID152 | B10: Marcus | C10: Valenzuela | D10: 39 | E10: Male | F10: Phoenix | G10: marcus.valenzuela@yahoo.com | H10: 694 Graham Prairie Apt. 887, Jimenezfurt, MI 33044 | I10: OID3528 | J10: 45040 | K10: 12:07:00 | L10: PID034 | M10: 275.44 | N10: 1 | O10: FLAT8 | P10: 7 | Q10: 63 | R10: 45042 | S10: 23:05:41 | T10: =_xlfn.CONCAT(B10," ",C10) -> Marcus Valenzuela | U10: =M10*N10 -> 275.44 | V10: =R10-J10 -> 2 | W10: =IF(O10="FLAT8",8%,IF(O10="FLAT10",10%,IF(O10="FLAT15",15%,IF(O10="FLAT20",20%,0)))) -> 0.08 | X10: =U10-(U10*W10)+IF(O10="DEL0",0,Q10) -> 316.4048 | Y10: =U10*W10 -> 22.0352 | Z10: =U10-Y10 -> 253.4048 | AA10: =Z10+IF(O10="DEL0",0,Q10) -> 316.4048 | AB10: =IF(V10>5,"Late",IF(V10=5,"Intime","BeforeTime")) -> BeforeTime | AC10: =TEXT(J10,"mmmm") -> April
A11: CID130 | B11: Debra | C11: Rodriguez | D11: 48 | E11: Other | F11: Houston | G11: debra.rodriguez@rediffmail.com | H11: Unit 5964 Box 0721, DPO AP 01840 | I11: OID9634 | J11: 45282 | K11: 13:46:47 | L11: PID033 | M11: 48.45 | N11: 1 | O11: FLAT15 | P11: 7 | Q11: 59 | R11: 45287 | S11: 19:57:06 | T11: =_xlfn.CONCAT(B11," ",C11) -> Debra Rodriguez | U11: =M11*N11 -> 48.45 | V11: =R11-J11 -> 5 | W11: =IF(O11="FLAT8",8%,IF(O11="FLAT10",10%,IF(O11="FLAT15",15%,IF(O11="FLAT20",20%,0)))) -> 0.15 | X11: =U11-(U11*W11)+IF(O11="DEL0",0,Q11) -> 100.1825 | Y11: =U11*W11 -> 7.2675 | Z11: =U11-Y11 -> 41.1825 | AA11: =Z11+IF(O11="DEL0",0,Q11) -> 100.1825 | AB11: =IF(V11>5,"Late",IF(V11=5,"Intime","BeforeTime")) -> Intime | AC11: =TEXT(J11,"mmmm") -> December
A12: CID115 | B12: Karl | C12: Gallagher | D12: 60 | E12: Other | F12: Phoenix | G12: karl.gallagher@rediffmail.com | H12: 5016 Snow Mountains Apt. 063, New Seanport, WY 41492 | I12: OID1905 | J12: 45588 | K12: 17:21:43 | L12: PID046 | M12: 363.64 | N12: 4 | O12: DEL0 | P12: 2 | Q12: 35 | R12: 45590 | S12: 08:00:35 | T12: =_xlfn.CONCAT(B12," ",C12) -> Karl Gallagher | U12: =M12*N12 -> 1454.56 | V12: =R12-J12 -> 2 | W12: =IF(O12="FLAT8",8%,IF(O12="FLAT10",10%,IF(O12="FLAT15",15%,IF(O12="FLAT20",20%,0)))) -> 0 | X12: =U12-(U12*W12)+IF(O12="DEL0",0,Q12) -> 1454.56 | Y12: =U12*W12 -> 0 | Z12: =U12-Y12 -> 1454.56 | AA12: =Z12+IF(O12="DEL0",0,Q12) -> 1454.56 | AB12: =IF(V12>5,"Late",IF(V12=5,"Intime","BeforeTime")) -> BeforeTime | AC12: =TEXT(J12,"mmmm") -> October
A13: CID101 | B13: Bobby | C13: Forbes | D13: 20 | E13: Male | F13: Los Angeles | G13: bobby.forbes@gmail.com | H13: 3079 John Parkway Suite 961, Port Kristaview, MT 91019 | I13: OID3136 | J13: 45498 | K13: 15:09:49 | L13: PID007 | M13: 257.06 | N13: 3 | O13: DEL0 | P13: 7 | Q13: 62 | R13: 45499 | S13: 22:54:40 | T13: =_xlfn.CONCAT(B13," ",C13) -> Bobby Forbes | U13: =M13*N13 -> 771.18 | V13: =R13-J13 -> 1 | W13: =IF(O13="FLAT8",8%,IF(O13="FLAT10",10%,IF(O13="FLAT15",15%,IF(O13="FLAT20",20%,0)))) -> 0 | X13: =U13-(U13*W13)+IF(O13="DEL0",0,Q13) -> 771.18 | Y13: =U13*W13 -> 0 | Z13: =U13-Y13 -> 771.18 | AA13: =Z13+IF(O13="DEL0",0,Q13) -> 771.18 | AB13: =IF(V13>5,"Late",IF(V13=5,"Intime","BeforeTime")) -> BeforeTime | AC13: =TEXT(J13,"mmmm") -> July
... A501: CID158 | B501: Angela | C501: Evans | D501: 52 | E501: Other | F501: Houston | G501: angela.evans@outlook.com | H501: 16031 David Mountain Suite 431, Susanborough, PA 01910 | I501: OID6847 | J501: 45501 | K501: 17:02:09 | L501: PID010 | M501: 44.5 | N501: 4 | O501: DEL0 | P501: 3 | Q501: 45 | R501: 45504 | S501: 05:55:32 | T501: =_xlfn.CONCAT(B501," ",C501) -> Angela Evans | U501: =M501*N501 -> 178 | V501: =R501-J501 -> 3 | W501: =IF(O501="FLAT8",8%,IF(O501="FLAT10",10%,IF(O501="FLAT15",15%,IF(O501="FLAT20",20%,0)))) -> 0 | X501: =U501-(U501*W501)+IF(O501="DEL0",0,Q501) -> 178 | Y501: =U501*W501 -> 0 | Z501: =U501-Y501 -> 178 | AA501: =Z501+IF(O501="DEL0",0,Q501) -> 178 | AB501: =IF(V501>5,"Late",IF(V501=5,"Intime","BeforeTime")) -> BeforeTime | AC501: =TEXT(J501,"mmmm") -> July
T502: =_xlfn.CONCAT(B502," ",C502) | AA502: =Z502+IF(O502="DEL0",0,Q502) -> 0 | AB502: =IF(V502>5,"Late",IF(V502=5,"Intime","BeforeTime")) -> BeforeTime | AC502: =TEXT(J502,"mmmm") -> January
P503: Total Orders with 0 Delivery = Charge | Q503: =COUNTIF(Q2:Q501,"=0") -> 0 | T503: =_xlfn.CONCAT(B503," ",C503) | AA503: =Z503+IF(O503="DEL0",0,Q503) -> 0 | AB503: =IF(V503>5,"Late",IF(V503=5,"Intime","BeforeTime")) -> BeforeTime | AC503: =TEXT(J503,"mmmm") -> January
T504: =_xlfn.CONCAT(B504," ",C504) | AA504: =Z504+IF(O504="DEL0",0,Q504) -> 0 | AB504: =IF(V504>5,"Late",IF(V504=5,"Intime","BeforeTime")) -> BeforeTime | AC504: =TEXT(J504,"mmmm") -> January
T505: =_xlfn.CONCAT(B505," ",C505) | AA505: =Z505+IF(O505="DEL0",0,Q505) -> 0 | AB505: =IF(V505>5,"Late",IF(V505=5,"Intime","BeforeTime")) -> BeforeTime | AC505: =TEXT(J505,"mmmm") -> January
T506: =_xlfn.CONCAT(B506," ",C506) | AA506: =Z506+IF(O506="DEL0",0,Q506) -> 0 | AB506: =IF(V506>5,"Late",IF(V506=5,"Intime","BeforeTime")) -> BeforeTime | AC506: =TEXT(J506,"mmmm") -> January
T507: =_xlfn.CONCAT(B507," ",C507) | AA507: =Z507+IF(O507="DEL0",0,Q507) -> 0 | AB507: =IF(V507>5,"Late",IF(V507=5,"Intime","BeforeTime")) -> BeforeTime | AC507: =TEXT(J507,"mmmm") -> January
T508: =_xlfn.CONCAT(B508," ",C508) | AA508: =Z508+IF(O508="DEL0",0,Q508) -> 0 | AB508: =IF(V508>5,"Late",IF(V508=5,"Intime","BeforeTime")) -> BeforeTime | AC508: =TEXT(J508,"mmmm") -> January
T509: =_xlfn.CONCAT(B509," ",C509) | AA509: =Z509+IF(O509="DEL0",0,Q509) -> 0 | AB509: =IF(V509>5,"Late",IF(V509=5,"Intime","BeforeTime")) -> BeforeTime | AC509: =TEXT(J509,"mmmm") -> January
T510: =_xlfn.CONCAT(B510," ",C510) | AA510: =Z510+IF(O510="DEL0",0,Q510) -> 0 | AB510: =IF(V510>5,"Late",IF(V510=5,"Intime","BeforeTime")) -> BeforeTime | AC510: =TEXT(J510,"mmmm") -> January
T511: =_xlfn.CONCAT(B511," ",C511) | AA511: =Z511+IF(O511="DEL0",0,Q511) -> 0 | AB511: =IF(V511>5,"Late",IF(V511=5,"Intime","BeforeTime")) -> BeforeTime | AC511: =TEXT(J511,"mmmm") -> January
T512: =_xlfn.CONCAT(B512," ",C512) | AA512: =Z512+IF(O512="DEL0",0,Q512) -> 0 | AB512: =IF(V512>5,"Late",IF(V512=5,"Intime","BeforeTime")) -> BeforeTime | AC512: =TEXT(J512,"mmmm") -> January
T513: =_xlfn.CONCAT(B513," ",C513) | AA513: =Z513+IF(O513="DEL0",0,Q513) -> 0 | AB513: =IF(V513>5,"Late",IF(V513=5,"Intime","BeforeTime")) -> BeforeTime | AC513: =TEXT(J513,"mmmm") -> January
T514: =_xlfn.CONCAT(B514," ",C514) | AA514: =Z514+IF(O514="DEL0",0,Q514) -> 0 | AB514: =IF(V514>5,"Late",IF(V514=5,"Intime","BeforeTime")) -> BeforeTime | AC514: =TEXT(J514,"mmmm") -> January
T515: =_xlfn.CONCAT(B515," ",C515) | AA515: =Z515+IF(O515="DEL0",0,Q515) -> 0 | AB515: =IF(V515>5,"Late",IF(V515=5,"Intime","BeforeTime")) -> BeforeTime | AC515: =TEXT(J515,"mmmm") -> January
... T526: =_xlfn.CONCAT(B526," ",C526) | AA526: =Z526+IF(O526="DEL0",0,Q526) -> 0 | AB526: =IF(V526>5,"Late",IF(V526=5,"Intime","BeforeTime")) -> BeforeTime | AC526: =TEXT(J526,"mmmm") -> January

Sheet KPI val calcualtion
A1: total customers | C1: =COUNTA(_xlfn.UNIQUE('Final Data '!T2:T501)) -> 100
A3: total orders | C3: =COUNTA('Final Data '!A2:A501) -> 500
A5: total product | C5: =COUNTA(_xlfn.UNIQUE('Final Data '!L2:L501)) -> 50
A7: total sales | C7: =SUM('Final Data '!U2:U502) -> 364289.49
A9: Amount after Discount & Delivery Charge | C9: =SUM('Final Data '!AA2:AA502) -> 347189.76
A11: Average Days to Deliver | C11: =AVERAGE('Final Data '!V2:V502) -> 4.002

Sheet Dashboard
A1: E-COMMERCE SALES DASHBOARD
U4: Total Orders
U5: ='KPI val calcualtion'!C3 -> 500
U8: Total Customers
U9: ='KPI val calcualtion'!C1 -> 100
U12: Total Products
U13: ='KPI val calcualtion'!C5 -> 50
U16: Total Sales
T17: $ | U17: ='KPI val calcualtion'!C7 -> 364289.49
U20: Amount after Discount &
U21: Delivery Charge
T22: $ | U22: ='KPI val calcualtion'!C9 -> 347189.76
U25: Average Days to Deliver
U26: 4 Days

Sheet Sheet6
A1: Delivery_Charge | B1: All
A3: Row Labels | B3: Sum of Order Amount2 | C3: Sum of Discounted Amount | D3: Sum of Amount After Discount | E3: Sum of Adjusted sales | F3: highest ordered product | G3: Distinct Count of Product_ID | H3: Distinct Count of Customer_ID | I3: Discount_Percent | J3: Count of Product_ID | K3: Count of Order_ID | L3: Average of Days it took for delivery | M3: Average of Age
A4: Aaron Thompson
A5: PID049 | B5: 2205.15 | C5: 176.412 | D5: 2028.738 | E5: 2090.738 | F5: 5 | G5: 1 | H5: 1 | I5: 0.08 | J5: 1 | K5: 1 | L5: 1 | M5: 47
A6: PID006 | B6: 955.04 | C6: 76.4032 | D6: 878.6368 | E6: 933.6368 | F6: 2 | G6: 1 | H6: 1 | I6: 0.08 | J6: 1 | K6: 1 | L6: 2 | M6: 47
A7: PID032 | B7: 849.64 | C7: 0 | D7: 849.64 | E7: 849.64 | F7: 2 | G7: 1 | H7: 1 | I7: 0 | J7: 1 | K7: 1 | L7: 7 | M7: 47
A8: PID036 | B8: 630.56 | C8: 50.4448 | D8: 580.1152 | E8: 624.1152 | F8: 4 | G8: 1 | H8: 1 | I8: 0.08 | J8: 1 | K8: 1 | L8: 7 | M8: 47
A9: PID042 | B9: 527.79 | C9: 0 | D9: 527.79 | E9: 527.79 | F9: 3 | G9: 1 | H9: 1 | I9: 0 | J9: 1 | K9: 1 | L9: 5 | M9: 47
A10: PID021 | B10: 259.5 | C10: 51.9 | D10: 207.6 | E10: 254.6 | F10: 2 | G10: 1 | H10: 1 | I10: 0.2 | J10: 1 | K10: 1 | L10: 3 | M10: 47
A11: Alexandra Smith
A12: PID006 | B12: 2387.6 | C12: 238.76 | D12: 2148.84 | E12: 2201.84 | F12: 5 | G12: 1 | H12: 1 | I12: 0.1 | J12: 1 | K12: 1 | L12: 2 | M12: 70
A13: PID027 | B13: 1444.44 | C13: 288.888 | D13: 1155.552 | E13: 1204.552 | F13: 3 | G13: 1 | H13: 1 | I13: 0.2 | J13: 1 | K13: 1 | L13: 7 | M13: 70
A14: PID038 | B14: 1265.1 | C14: 0 | D14: 1265.1 | E14: 1265.1 | F14: 3 | G14: 1 | H14: 1 | I14: 0 | J14: 1 | K14: 1 | L14: 5 | M14: 70
A15: PID023 | B15: 1012.7 | C15: 151.905 | D15: 860.795 | E15: 907.795 | F15: 5 | G15: 1 | H15: 1 | I15: 0.15 | J15: 1 | K15: 1 | L15: 6 | M15: 70
A16: PID045 | B16: 167.45 | C16: 33.49 | D16: 133.96 | E16: 197.96 | F16: 5 | G16: 1 | H16: 1 | I16: 0.2 | J16: 1 | K16: 1 | L16: 6 | M16: 70
A17: PID003 | B17: 41.4 | C17: 4.14 | D17: 37.26 | E17: 87.26 | F17: 2 | G17: 1 | H17: 1 | I17: 0.1 | J17: 1 | K17: 1 | L17: 2 | M17: 70
A18: Amanda Howard
A19: PID017 | B19: 1276.77 | C19: 102.1416 | D19: 1174.6284 | E19: 1242.6284 | F19: 3 | G19: 1 | H19: 1 | I19: 0.08 | J19: 1 | K19: 1 | L19: 4 | M19: 52
A20: PID032 | B20: 849.64 | C20: 0 | D20: 849.64 | E20: 849.64 | F20: 2 | G20: 1 | H20: 1 | I20: 0 | J20: 1 | K20: 1 | L20: 5 | M20: 52
A21: PID030 | B21: 847.89 | C21: 67.8312 | D21: 780.0588 | E21: 816.0588 | F21: 3 | G21: 1 | H21: 1 | I21: 0.08 | J21: 1 | K21: 1 | L21: 7 | M21: 52
A22: PID043 | B22: 660.22 | C22: 0 | D22: 660.22 | E22: 660.22 | F22: 2 | G22: 1 | H22: 1 | I22: 0 | J22: 1 | K22: 1 | L22: 1 | M22: 52
A23: PID026 | B23: 640.7 | C23: 96.105 | D23: 544.595 | E23: 601.595 | F23: 5 | G23: 1 | H23: 1 | I23: 0.15 | J23: 1 | K23: 1 | L23: 2 | M23: 52
A24: PID003 | B24: 41.4 | C24: 3.312 | D24: 38.088 | E24: 77.088 | F24: 2 | G24: 1 | H24: 1 | I24: 0.08 | J24: 1 | K24: 1 | L24: 7 | M24: 52
A25: Amy Ellis
A26: PID025 | B26: 2015.15 | C26: 302.2725 | D26: 1712.8775 | E26: 1818.8775 | F26: 5 | G26: 1 | H26: 1 | I26: 0.3 | J26: 2 | K26: 2 | L26: 6 | M26: 44
A27: PID001 | B27: 1476.12 | C27: 295.224 | D27: 1180.896 | E27: 1236.896 | F27: 4 | G27: 1 | H27: 1 | I27: 0.2 | J27: 1 | K27: 1 | L27: 5 | M27: 44
A28: PID013 | B28: 1178.15 | C28: 235.63 | D28: 942.52 | E28: 1005.52 | F28: 5 | G28: 1 | H28: 1 | I28: 0.2 | J28: 1 | K28: 1 | L28: 5 | M28: 44
A29: PID015 | B29: 665.12 | C29: 133.024 | D29: 532.096 | E29: 568.096 | F29: 4 | G29: 1 | H29: 1 | I29: 0.2 | J29: 1 | K29: 1 | L29: 7 | M29: 44
A30: PID026 | B30: 384.42 | C30: 76.884 | D30: 307.536 | E30: 356.536 | F30: 3 | G30: 1 | H30: 1 | I30: 0.2 | J30: 1 | K30: 1 | L30: 6 | M30: 44
A31: PID010 | B31: 89 | C31: 13.35 | D31: 75.65 | E31: 127.65 | F31: 2 | G31: 1 | H31: 1 | I31: 0.15 | J31: 1 | K31: 1 | L31: 2 | M31: 44
A32: PID045 | B32: 33.49 | C32: 2.6792 | D32: 30.8108 | E32: 97.8108 | F32: 1 | G32: 1 | H32: 1 | I32: 0.08 | J32: 1 | K32: 1 | L32: 1 | M32: 44
A33: Amy Griffin
A34: PID004 | B34: 2482.95 | C34: 198.636 | D34: 2284.314 | E34: 2345.314 | F34: 5 | G34: 1 | H34: 1 | I34: 0.08 | J34: 1 | K34: 1 | L34: 2 | M34: 29
A35: PID027 | B35: 1925.92 | C35: 0 | D35: 1925.92 | E35: 1925.92 | F35: 4 | G35: 1 | H35: 1 | I35: 0 | J35: 1 | K35: 1 | L35: 5 | M35: 29
A36: PID012 | B36: 398.91 | C36: 59.8365 | D36: 339.0735 | E36: 375.0735 | F36: 3 | G36: 1 | H36: 1 | I36: 0.15 | J36: 1 | K36: 1 | L36: 2 | M36: 29
A37: PID033 | B37: 96.9 | C37: 14.535 | D37: 82.365 | E37: 138.365 | F37: 2 | G37: 1 | H37: 1 | I37: 0.15 | J37: 1 | K37: 1 | L37: 6 | M37: 29
A38: Amy Reid
A39: PID020 | B39: 1725.76 | C39: 258.864 | D39: 1466.896 | E39: 1532.896 | F39: 4 | G39: 1 | H39: 1 | I39: 0.15 | J39: 1 | K39: 1 | L39: 1 | M39: 44
A40: PID041 | B40: 1117.86 | C40: 89.4288 | D40: 1028.4312 | E40: 1080.4312 | F40: 3 | G40: 1 | H40: 1 | I40: 0.08 | J40: 1 | K40: 1 | L40: 7 | M40: 44
A41: PID039 | B41: 440.54 | C41: 0 | D41: 440.54 | E41: 440.54 | F41: 2 | G41: 1 | H41: 1 | I41: 0 | J41: 1 | K41: 1 | L41: 5 | M41: 44
...

Sheet Sheet7
A3: Row Labels | B3: Amount_with_delivery_charge
A4: Angela Evans | B4: 6606.2737
A5: Brendan Kelly | B5: 6567.3072
A6: Jessica Ruiz | B6: 6854.0678
A7: Jodi Whitney | B7: 13056.679
A8: John Herrera | B8: 6576.1846 | F8: top 10 customers with highest Total Sales
A9: Katherine Weber | B9: 6564.2684
A10: Lauren Crane | B10: 8218.4583
A11: Lauren Long | B11: 6685.0841
A12: Mark Summers | B12: 7874.7187
A13: Mary Knight | B13: 7451.5638
A14: Grand Total | B14: 76454.606

Sheet Sheet8
A3: Row Labels | B3: Count of Product_ID
A4: PID001 | B4: 11 | G4: top 7 most ordered products and its percentage
A5: PID002 | B5: 14
A6: PID003 | B6: 12
A7: PID004 | B7: 11
A8: Grand Total | B8: 48

Sheet Sheet9
A3: Row Labels | B3: Count of Order_ID
A4: San Francisco | B4: 72
A5: Phoenix | B5: 66 | G5: city wise Total orders on a bar Chart
A6: New York | B6: 51
A7: Miami | B7: 44
A8: Los Angeles | B8: 72
A9: Houston | B9: 80
A10: Dallas | B10: 64
A11: Chicago | B11: 51
A12: Grand Total | B12: 500

Sheet Sheet11
A3: Row Labels | B3: Sum of Amount_with_delivery_charge
A4: (blank) | B4: 0
A5: Chicago | B5: 33234.737
A6: Dallas | B6: 46047.757
A7: Houston | B7: 60148.81
A8: Los Angeles | B8: 47533.306
A9: Miami | B9: 24762.065 | G9: city wise Total Amount after discount and delivery charge on a bar chart
A10: New York | B10: 39809.198
A11: Phoenix | B11: 45607.426
A12: San Francisco | B12: 50046.461
A13: Grand Total | B13: 347189.76

Sheet Sheet12
A3: Row Labels | B3: Count of Coupon_Code
A4: DEL0 | B4: 102
A5: FLAT10 | B5: 100
A6: FLAT15 | B6: 83 | G6: Count of all different Discount Coupon used on a Pie Chart
A7: FLAT20 | B7: 104
A8: FLAT8 | B8: 111
A9: Grand Total | B9: 500

Sheet Sheet13
A3: Sum of Amount_with_delivery_charge | B3: Column Labels
A4: Row Labels | B4: Female | C4: Male | D4: Grand Total
A5: April | B5: 16094.932 | C5: 10241.587 | D5: 26336.519
A6: August | B6: 10309.337 | C6: 8244.1471 | D6: 18553.484
A7: December | B7: 5307.2116 | C7: 6295.1011 | D7: 11602.313
A8: February | B8: 9383.2883 | C8: 7999.712 | D8: 17383
A9: January | B9: 8150.0288 | C9: 6482.6481 | D9: 14632.677
A10: July | B10: 8454.1744 | C10: 14543.007 | D10: 22997.182
A11: June | B11: 10185.533 | C11: 10543.313 | D11: 20728.845
A12: March | B12: 11079.175 | C12: 7791.678 | D12: 18870.853
A13: May | B13: 3690.165 | C13: 8286.7198 | D13: 11976.885
A14: November | B14: 3964.8176 | C14: 5559 | D14: 9523.8176
A15: October | B15: 8193.9499 | C15: 9548.1745 | D15: 17742.124
A16: September | B16: 5620.5067 | C16: 9875.9237 | D16: 15496.43
A17: Grand Total | B17: 100433.12 | C17: 105411.01 | D17: 205844.13
